<robot
  name="deneme">
  <link
    name="base_link">
    <inertial>
      <origin
        xyz="2.78908912487736E-07 4.32677236495861E-09 0.0338359867815315"
        rpy="0 0 0" />
      <mass
        value="2.7" />
      <inertia
        ixx="0.0426806445818626"
        ixy="-1.3325338701662E-07"
        ixz="-2.90513784415753E-09"
        iyy="0.0322795745013942"
        iyz="4.56860172279951E-08"
        izz="0.0698698216971901" />
    </inertial>
    <visual>
      <origin
        xyz="0 0 0"
        rpy="0 0 0" />
      <geometry>
        <mesh
          filename="package://pr2_description/meshes/base_link.stl" />
      </geometry>
      <material
        name="">
        <color
          rgba="0.792156862745098 0.819607843137255 0.933333333333333 1" />
      </material>
    </visual>
    <collision>
      <origin
        xyz="0 0 0"
        rpy="0 0 0" />
      <geometry>
        <mesh
          filename="package://pr2_description/meshes/base_link.stl" />
      </geometry>
    </collision>
  </link>
  <link
    name="m1">
    <inertial>
      <origin
        xyz="2.7891E-07 4.3268E-09 0.033836"
        rpy="0 0 0" />
      <mass
        value="2.7" />
      <inertia
        ixx="0.042681"
        ixy="-1.3325E-07"
        ixz="-2.9051E-09"
        iyy="0.03228"
        iyz="4.5686E-08"
        izz="0.06987" />
    </inertial>
    <visual>
      <origin
        xyz="0 0 0"
        rpy="0 0 0" />
      <geometry>
        <mesh
          filename="package://pr2_description/meshes/m1.stl" />
      </geometry>
      <material
        name="">
        <color
          rgba="0.79216 0.81961 0.93333 1" />
      </material>
    </visual>
    <collision>
      <origin
        xyz="0 0 0"
        rpy="0 0 0" />
      <geometry>
        <mesh
          filename="package://pr2_description/meshes/m1.stl" />
      </geometry>
    </collision>
  </link>
  <joint
    name="m1_motor"
    type="continuous">
    <origin
      xyz="-0.032228 0.059955 0.072647"
      rpy="1.5708 0.0052321 -1.5507" />
    <parent
      link="base_link" />
    <child
      link="m1" />
    <axis
      xyz="0 0 -1" />
  </joint>
  <link
    name="w1">
    <inertial>
      <origin
        xyz="2.78908912487736E-07 4.32677236495861E-09 0.0338359867815315"
        rpy="0 0 0" />
      <mass
        value="2.7" />
      <inertia
        ixx="0.0426806445818626"
        ixy="-1.3325338701662E-07"
        ixz="-2.90513784415753E-09"
        iyy="0.0322795745013942"
        iyz="4.56860172279951E-08"
        izz="0.0698698216971901" />
    </inertial>
    <visual>
      <origin
        xyz="0 0 0"
        rpy="0 0 0" />
      <geometry>
        <mesh
          filename="package://pr2_description/meshes/w1.stl" />
      </geometry>
      <material
        name="">
        <color
          rgba="0.298039215686275 0.298039215686275 0.298039215686275 1" />
      </material>
    </visual>
    <collision>
      <origin
        xyz="0 0 0"
        rpy="0 0 0" />
      <geometry>
        <mesh
          filename="package://pr2_description/meshes/w1.stl" />
      </geometry>
    </collision>
  </link>
  <joint
    name="w1_joint"
    type="continuous">
    <origin
      xyz="0 0 0.05"
      rpy="-2.3558E-15 -3.0011E-16 1.0123" />
    <parent
      link="m1" />
    <child
      link="w1" />
    <axis
      xyz="0 0 -1" />
  </joint>
  <link
    name="m2">
    <inertial>
      <origin
        xyz="2.78908912487736E-07 4.32677236495861E-09 0.0338359867815315"
        rpy="0 0 0" />
      <mass
        value="2.7" />
      <inertia
        ixx="0.0426806445818626"
        ixy="-1.3325338701662E-07"
        ixz="-2.90513784415753E-09"
        iyy="0.0322795745013942"
        iyz="4.56860172279951E-08"
        izz="0.0698698216971901" />
    </inertial>
    <visual>
      <origin
        xyz="0 0 0"
        rpy="0 0 0" />
      <geometry>
        <mesh
          filename="package://pr2_description/meshes/m2.stl" />
      </geometry>
      <material
        name="">
        <color
          rgba="0.792156862745098 0.819607843137255 0.933333333333333 1" />
      </material>
    </visual>
    <collision>
      <origin
        xyz="0 0 0"
        rpy="0 0 0" />
      <geometry>
        <mesh
          filename="package://pr2_description/meshes/m2.stl" />
      </geometry>
    </collision>
  </link>
  <joint
    name="m2_joint"
    type="continuous">
    <origin
      xyz="0.032215 0.060032 0.072647"
      rpy="1.5708 1.3042 1.5854" />
    <parent
      link="base_link" />
    <child
      link="m2" />
    <axis
      xyz="0 0 1" />
  </joint>
  <link
    name="w2">
    <inertial>
      <origin
        xyz="2.78908912487736E-07 4.32677236495861E-09 0.0338359867815315"
        rpy="0 0 0" />
      <mass
        value="2.7" />
      <inertia
        ixx="0.0426806445818626"
        ixy="-1.3325338701662E-07"
        ixz="-2.90513784415753E-09"
        iyy="0.0322795745013942"
        iyz="4.56860172279951E-08"
        izz="0.0698698216971901" />
    </inertial>
    <visual>
      <origin
        xyz="0 0 0"
        rpy="0 0 0" />
      <geometry>
        <mesh
          filename="package://pr2_description/meshes/w2.stl" />
      </geometry>
      <material
        name="">
        <color
          rgba="0.298039215686275 0.298039215686275 0.298039215686275 1" />
      </material>
    </visual>
    <collision>
      <origin
        xyz="0 0 0"
        rpy="0 0 0" />
      <geometry>
        <mesh
          filename="package://pr2_description/meshes/w2.stl" />
      </geometry>
    </collision>
  </link>
  <joint
    name="w2_joint"
    type="continuous">
    <origin
      xyz="0 0 0.05"
      rpy="3.1416 -2.498E-16 -1.4782" />
    <parent
      link="m2" />
    <child
      link="w2" />
    <axis
      xyz="0 0 -1" />
  </joint>
  <link
    name="m3">
    <inertial>
      <origin
        xyz="2.78908912487736E-07 4.32677236495861E-09 0.0338359867815315"
        rpy="0 0 0" />
      <mass
        value="2.7" />
      <inertia
        ixx="0.0426806445818626"
        ixy="-1.3325338701662E-07"
        ixz="-2.90513784415753E-09"
        iyy="0.0322795745013942"
        iyz="4.56860172279951E-08"
        izz="0.0698698216971901" />
    </inertial>
    <visual>
      <origin
        xyz="0 0 0"
        rpy="0 0 0" />
      <geometry>
        <mesh
          filename="package://pr2_description/meshes/m3.stl" />
      </geometry>
      <material
        name="">
        <color
          rgba="0.792156862745098 0.819607843137255 0.933333333333333 1" />
      </material>
    </visual>
    <collision>
      <origin
        xyz="0 0 0"
        rpy="0 0 0" />
      <geometry>
        <mesh
          filename="package://pr2_description/meshes/m3.stl" />
      </geometry>
    </collision>
  </link>
  <joint
    name="m3_joint"
    type="continuous">
    <origin
      xyz="-0.032228 0.059955 -0.073353"
      rpy="1.5708 1.3834 -1.5507" />
    <parent
      link="base_link" />
    <child
      link="m3" />
    <axis
      xyz="0 0 -1" />
  </joint>
  <link
    name="w3">
    <inertial>
      <origin
        xyz="2.78908912487736E-07 4.32677236495861E-09 0.0338359867815315"
        rpy="0 0 0" />
      <mass
        value="2.7" />
      <inertia
        ixx="0.0426806445818626"
        ixy="-1.3325338701662E-07"
        ixz="-2.90513784415753E-09"
        iyy="0.0322795745013942"
        iyz="4.56860172279951E-08"
        izz="0.0698698216971901" />
    </inertial>
    <visual>
      <origin
        xyz="0 0 0"
        rpy="0 0 0" />
      <geometry>
        <mesh
          filename="package://pr2_description/meshes/w3.stl" />
      </geometry>
      <material
        name="">
        <color
          rgba="0.298039215686275 0.298039215686275 0.298039215686275 1" />
      </material>
    </visual>
    <collision>
      <origin
        xyz="0 0 0"
        rpy="0 0 0" />
      <geometry>
        <mesh
          filename="package://pr2_description/meshes/w3.stl" />
      </geometry>
    </collision>
  </link>
  <joint
    name="w3_joint"
    type="continuous">
    <origin
      xyz="0 0 0.05"
      rpy="8.1185E-16 -3.1572E-16 2.3941" />
    <parent
      link="m3" />
    <child
      link="w3" />
    <axis
      xyz="0 0 -1" />
  </joint>
  <link
    name="m4">
    <inertial>
      <origin
        xyz="2.78908912487736E-07 4.32677236495861E-09 0.0338359867815315"
        rpy="0 0 0" />
      <mass
        value="2.7" />
      <inertia
        ixx="0.0426806445818626"
        ixy="-1.3325338701662E-07"
        ixz="-2.90513784415753E-09"
        iyy="0.0322795745013942"
        iyz="4.56860172279951E-08"
        izz="0.0698698216971901" />
    </inertial>
    <visual>
      <origin
        xyz="0 0 0"
        rpy="0 0 0" />
      <geometry>
        <mesh
          filename="package://pr2_description/meshes/m4.stl" />
      </geometry>
      <material
        name="">
        <color
          rgba="0.792156862745098 0.819607843137255 0.933333333333333 1" />
      </material>
    </visual>
    <collision>
      <origin
        xyz="0 0 0"
        rpy="0 0 0" />
      <geometry>
        <mesh
          filename="package://pr2_description/meshes/m4.stl" />
      </geometry>
    </collision>
  </link>
  <joint
    name="m4_joint"
    type="continuous">
    <origin
      xyz="0.032202 0.060013 -0.073353"
      rpy="1.5708 0.04959 1.5766" />
    <parent
      link="base_link" />
    <child
      link="m4" />
    <axis
      xyz="0 0 1" />
  </joint>
  <link
    name="w4">
    <inertial>
      <origin
        xyz="2.78908912487736E-07 4.32677236495861E-09 0.0338359867815315"
        rpy="0 0 0" />
      <mass
        value="2.7" />
      <inertia
        ixx="0.0426806445818626"
        ixy="-1.3325338701662E-07"
        ixz="-2.90513784415753E-09"
        iyy="0.0322795745013942"
        iyz="4.56860172279951E-08"
        izz="0.0698698216971901" />
    </inertial>
    <visual>
      <origin
        xyz="0 0 0"
        rpy="0 0 0" />
      <geometry>
        <mesh
          filename="package://pr2_description/meshes/w4.stl" />
      </geometry>
      <material
        name="">
        <color
          rgba="0.298039215686275 0.298039215686275 0.298039215686275 1" />
      </material>
    </visual>
    <collision>
      <origin
        xyz="0 0 0"
        rpy="0 0 0" />
      <geometry>
        <mesh
          filename="package://pr2_description/meshes/w4.stl" />
      </geometry>
    </collision>
  </link>
  <joint
    name="w4_joint"
    type="continuous">
    <origin
      xyz="0 0 0.05"
      rpy="-3.1416 1.6046E-16 0.14359" />
    <parent
      link="m4" />
    <child
      link="w4" />
    <axis
      xyz="0 0 -1" />
  </joint>
</robot>
